Workbook

Sheet Geral
H2: Extrato BB 2025 Geral
C4: Janeiro | D4: Fevereiro | E4: Março | F4: Abril | G4: Maio | H4: Junho | I4: Agosto | J4: Setembro | K4: Outubro | L4: Novembro | M4: Dezembro
B5: SESAP | C5: =Jan!J1 -> 540014.34 | D5: =Fev!J1 -> 547072.6 | E5: =Mar!I1 -> 354538.76 | F5: =Abr!M1 -> 786969.58 | G5: =Mai!M1 -> 828438.8 | H5: =Jun!M1 -> 954127.35 | I5: 0 | J5: 0 | K5: 0 | L5: 0 | M5: 0
L8: Geral | M8: =SUM(C5:M5) -> 4011161.4
H12: Extrato BB 2025 Hematologia
C14: Janeiro | D14: Fevereiro | E14: Março | F14: Abril | G14: Maio | H14: Junho | I14: Agosto | J14: Setembro | K14: Outubro | L14: Novembro | M14: Dezembro
C15: =Jan!J11 -> 0 | D15: =Fev!J11 -> 0 | E15: =Mar!I10 -> 0 | F15: =Abr!K1 -> 88043.08 | G15: =Mai!K1 -> 162800.05 | H15: 0 | I15: 0 | J15: 0 | K15: 0 | L15: 0 | M15: 0
L18: Geral | M18: =SUM(C15:M15) -> 250843.13
H22: Extrato BB 2025 Coagulação
C24: Janeiro | D24: Fevereiro | E24: Março | F24: Abril | G24: Maio | H24: Junho | I24: Agosto | J24: Setembro | K24: Outubro | L24: Novembro | M24: Dezembro
C25: =Jan!J21 -> 0 | D25: =Fev!J21 -> 0 | F25: =Abr!K60 -> 10125.28 | G25: =Mai!K8 -> 22726.57 | H25: =Jun!K7 -> 3753.14 | I25: 0 | J25: 0 | K25: 0 | L25: 0 | M25: 0
L28: Geral | M28: =SUM(C25:M25) -> 36604.99
H33: Extrato BB 2025 TT/TTPA
C35: Janeiro | D35: Fevereiro | E35: Março | F35: Abril | G35: Maio | H35: Junho | I35: Agosto | J35: Setembro | K35: Outubro | L35: Novembro | M35: Dezembro
C36: =Jan!J32 -> 0 | D36: =Fev!J32 -> 0 | E36: =Mar!I31 -> 0 | F36: =Abr!K62 -> 4462.09 | G36: 0 | H36: 0 | I36: 0 | J36: 0 | K36: 0 | L36: 0 | M36: 0
L39: Geral | M39: =SUM(C36:M36) -> 4462.09
H43: Extrato BB 2025 Ionograma
C45: Janeiro | D45: Fevereiro | E45: Março | F45: Abril | G45: Maio | H45: Junho | I45: Agosto | J45: Setembro | K45: Outubro | L45: Novembro | M45: Dezembro
C46: =Jan!J42 -> 0 | D46: =Fev!J42 -> 0 | E46: =Mar!I41 -> 0 | F46: =Abr!K64 -> 0 | G46: =Mai!K12 -> 3910.44 | H46: 0 | I46: 0 | J46: 0 | K46: 0 | L46: 0 | M46: 0
L49: Geral | M49: =SUM(C46:M46) -> 3910.44

Sheet Jan
A1: Status | B1: Dt. balancete | C1: Ag. origem | D1: Lote | E1: Histórico | F1: Documento | G1: Valor R$ | H1: Observações | J1: =SUBTOTAL(9,Jan!$G$2:$G$618) -> 540014.34
B2: 45657 | C2: 0 | D2: 0 | E2: 000 Saldo Anterior
B3: 45659 | C3: 3525 | D3: 99021 | E3: 870 Transferência recebida | F3: 613525000032047 | G3: 631.8
E4: 02/01 09:49 D&M LABORATORIO DE ANALI
B5: 45659 | C5: 1533 | D5: 99008 | E5: 234 Compra com Cartão | F5: 949158 | G5: 305.71
E6: 02/01 11:37 POSTO SENADOR
B7: 45659 | C7: 0 | D7: 13105 | E7: 109 Pagamento de Boleto | F7: 10201 | G7: 12650.09
E8: APPARAT BRASIL COMERCIO DE REA
B9: 45659 | C9: 0 | D9: 13105 | E9: 109 Pagamento de Boleto | F9: 10202 | G9: 3195.4
E10: TICKET SERVICOS SA
B11: 45659 | C11: 0 | D11: 13105 | E11: 363 Pagto conta telefone | F11: 10203 | G11: 131.01
E12: VIVO RN
B13: 45659 | C13: 0 | D13: 13105 | E13: 109 Pagamento de Boleto | F13: 10204 | G13: 675.6
E14: LABORLAB PROD PARA LAB LTDA
B15: 45659 | C15: 0 | D15: 13105 | E15: 109 Pagamento de Boleto | F15: 10205 | G15: 1392.35
E16: CONFIANCA FUNDO DE INVEST EM D
B17: 45659 | C17: 0 | D17: 13105 | E17: 109 Pagamento de Boleto | F17: 10206 | G17: 686.24
E18: BANCO SOFISA S/A
B19: 45659 | C19: 0 | D19: 13105 | E19: 109 Pagamento de Boleto | F19: 10207 | G19: 1539.04
E20: BIO ADVANCE D LTDA EPP
B21: 45659 | C21: 0 | D21: 13105 | E21: 109 Pagamento de Boleto | F21: 10208 | G21: 1050.34
E22: BIOSYN INDUSTRIA E COMERCIO DE
B23: 45659 | C23: 0 | D23: 13105 | E23: 109 Pagamento de Boleto | F23: 10209 | G23: 283.89
E24: BR COMERCIO DE ELETRONICOS LTD
B25: 45659 | C25: 0 | D25: 13105 | E25: 109 Pagamento de Boleto | F25: 10210 | G25: 256.76
E26: BR COMERCIO DE ELETRONICOS LTD
B27: 45659 | C27: 0 | D27: 13105 | E27: 109 Pagamento de Boleto | F27: 10211 | G27: 233.17
E28: BR COMERCIO DE ELETRONICOS LTD
B29: 45659 | C29: 0 | D29: 13105 | E29: 109 Pagamento de Boleto | F29: 10212 | G29: 204.96
E30: J T A COMERCIO SERVICOS LTDA
B31: 45659 | C31: 0 | D31: 13105 | E31: 109 Pagamento de Boleto | F31: 10213 | G31: 49.9
E32: PJBANK PAGAMENTOS S A_1
B33: 45659 | C33: 0 | D33: 13105 | E33: 109 Pagamento de Boleto | F33: 10214 | G33: 569.46
E34: STER BOM IND. E COM. LTDA
B35: 45659 | C35: 0 | D35: 13105 | E35: 363 Pagto conta telefone | F35: 10215 | G35: 33.43
E36: VIVO RN
B37: 45659 | C37: 0 | D37: 13105 | E37: 109 Pagamento de Boleto | F37: 10216 | G37: 383.86
E38: POLIFARMA DISTRIBUIDORA DE MED
B39: 45659 | C39: 0 | D39: 13105 | E39: 109 Pagamento de Boleto | F39: 10217 | G39: 1553.15
E40: DISTR DE MEDI SANTA CRUZ LTDA
...

Sheet Fev
A1: Status | B1: Dt. balancete | C1: Ag. origem | D1: Lote | E1: Histórico | F1: Documento | G1: Valor R$ | H1: Observações | J1: =SUBTOTAL(9,Fev!$G$2:$G$606) -> 547072.6
B2: 45688 | C2: 0 | D2: 0 | E2: 000 Saldo Anterior
B3: 45691 | C3: 1845 | D3: 99021 | E3: 870 Transferência recebida | F3: 611845000040070 | G3: 1015.98
E4: 03/02 08:09 RP SERVICOS LABORATORIAI
B5: 45691 | C5: 0 | D5: 14175 | E5: 976 TED-Crédito em Conta | F5: 368466185 | G5: 6000
E6: 748 2207 03319496000159 MEDCAL FARMA H
B7: 45691 | C7: 0 | D7: 13105 | E7: 109 Pagamento de Boleto | F7: 20301 | G7: 339.9
E8: RV TECNOLOGIA S A
B9: 45691 | C9: 0 | D9: 13105 | E9: 375 Impostos | F9: 20302 | G9: 1907.51
E10: RN TRIBUTACAO ICMS
B11: 45691 | C11: 0 | D11: 13105 | E11: 375 Impostos | F11: 20303 | G11: 23.55
E12: RN TRIBUTACAO ICMS
B13: 45691 | C13: 0 | D13: 13105 | E13: 363 Pagto conta telefone | F13: 20304 | G13: 957.81
E14: TIM S/A
B15: 45691 | C15: 0 | D15: 13105 | E15: 109 Pagamento de Boleto | F15: 20305 | G15: 49.9
E16: PJBANK PAGAMENTOS S A_1
B17: 45691 | C17: 0 | D17: 13105 | E17: 109 Pagamento de Boleto | F17: 20306 | G17: 3216.46
E18: EBRAM PROD LABORATORIAIS LTDA
B19: 45691 | C19: 0 | D19: 13105 | E19: 109 Pagamento de Boleto | F19: 20307 | G19: 450.76
E20: DISTR DE MEDI SANTA CRUZ LTDA
B21: 45691 | C21: 0 | D21: 13105 | E21: 109 Pagamento de Boleto | F21: 20308 | G21: 33.73
E22: DISTR DE MEDI SANTA CRUZ LTDA
B23: 45691 | C23: 0 | D23: 13105 | E23: 109 Pagamento de Boleto | F23: 20309 | G23: 1145.18
E24: DPC DISTRIBUIDOR ATACADISTA S
B25: 45691 | C25: 0 | D25: 0 | E25: 798 BB Rende Fácil | F25: 9903 | G25: 1108.82
E26: Rende Facil
B27: 45692 | C27: 0 | D27: 14397 | E27: 821 Pix - Recebido | F27: 41337405446532 | G27: 2000
E28: 04/02 13:37 03319496000159 MEDCAL FARM
A29: Baixado | B29: 45692 | C29: 0 | D29: 14138 | E29: 632 Ordem Bancária | F29: 202502030059176 | G29: 2877.71 | H29: FATURA 3191.1 CONJUNTO DE SOLU ES,RE
E30: ESTADO DO RIO GRANDE D
A31: Baixado | B31: 45692 | C31: 0 | D31: 14138 | E31: 632 Ordem Bancária | F31: 202502030059178 | G31: 1232.84 | H31: FATURA 3191.1 CONJUNTO DE SOLU ES,RE
E32: ESTADO DO RIO GRANDE D
A33: Baixado | B33: 45692 | C33: 0 | D33: 14138 | E33: 632 Ordem Bancária | F33: 202502030059180 | G33: 804.25 | H33: FATURA 3272.1 COMP. 12 24 - CONJUNTO
E34: ESTADO DO RIO GRANDE D
A35: Baixado | B35: 45692 | C35: 0 | D35: 14138 | E35: 632 Ordem Bancária | F35: 202502030059182 | G35: 1668.08 | H35: FATURA 3272.1 COMP. 12 24 - CONJUNTO
E36: ESTADO DO RIO GRANDE D
A37: Baixado | B37: 45692 | C37: 0 | D37: 14138 | E37: 632 Ordem Bancária | F37: 202502030059188 | G37: 9096.92 | H37: FTs 3261 e 3240 - COMP 12 2024, ref. ao
E38: ESTADO DO RIO GRANDE D
B39: 45692 | C39: 0 | D39: 13105 | E39: 375 Impostos | F39: 20401 | G39: 175.72
E40: RN TRIBUTACAO ICMS
...

Sheet Mar
A1: Status | B1: Dt. balancete | C1: Ag. origem | D1: Lote | E1: Histórico | F1: Documento | G1: Valor R$ | H1: TOTAL | I1: =SUBTOTAL(9,Mar!$G$2:$G$478) -> 354538.76
B2: 45721 | C2: 0 | D2: 14175 | E2: 976 TED-Crédito em Conta | F2: 372406878 | G2: 5000
E3: 748 2207 03319496000159 MEDCAL FARMA H | G3: 0
A4: Baixado | B4: 45721 | C4: 0 | D4: 14138 | E4: 632 Ordem Bancária | F4: 202502280062948 | G4: 1024.16 | H4: 3263
E5: ESTADO DO RIO GRANDE D | G5: 0
A6: Baixado | B6: 45721 | C6: 0 | D6: 14138 | E6: 632 Ordem Bancária | F6: 202502280062949 | G6: 1668.08 | H6: 3239
E7: ESTADO DO RIO GRANDE D | G7: 0
B8: 45721 | C8: 1533 | D8: 99008 | E8: 234 Compra com Cartão | F8: 91862 | G8: 227.3
E9: 03/03 20:05 POSTO DINIZ - EMAUS | G9: 0
B10: 45721 | C10: 0 | D10: 13105 | E10: 109 Pagamento de Boleto | F10: 30501 | G10: 49.9
E11: PJBANK PAGAMENTOS S A_1 | G11: 0
B12: 45721 | C12: 0 | D12: 13105 | E12: 109 Pagamento de Boleto | F12: 30502 | G12: 736.36
E13: APPARAT BRASIL C R I LTDA | G13: 0
B14: 45721 | C14: 0 | D14: 13105 | E14: 109 Pagamento de Boleto | F14: 30503 | G14: 187.2
E15: CRIL EMPREENDIMENTO AMBIENTAL | G15: 0
B16: 45721 | C16: 0 | D16: 13105 | E16: 109 Pagamento de Boleto | F16: 30504 | G16: 393.58
E17: KATAL BIOTECNOLOGICA INDUSTRIA | G17: 0
B18: 45721 | C18: 0 | D18: 13105 | E18: 109 Pagamento de Boleto | F18: 30505 | G18: 2282.77
E19: KATAL BIOTECNOLOGICA INDUSTRIA | G19: 0
B20: 45721 | C20: 0 | D20: 13105 | E20: 109 Pagamento de Boleto | F20: 30506 | G20: 817.82
E21: MEDIARTE COMERCIO E SERVICOS D | G21: 0
B22: 45721 | C22: 0 | D22: 13105 | E22: 109 Pagamento de Boleto | F22: 30507 | G22: 305.44
E23: STER BOM IND. E COM. LTDA | G23: 0
B24: 45721 | C24: 0 | D24: 13105 | E24: 109 Pagamento de Boleto | F24: 30508 | G24: 392.62
E25: STER BOM IND. E COM. LTDA | G25: 0
B26: 45721 | C26: 0 | D26: 13105 | E26: 109 Pagamento de Boleto | F26: 30509 | G26: 2617.4
E27: TICKET SERVICOS SA | G27: 0
B28: 45721 | C28: 0 | D28: 13105 | E28: 109 Pagamento de Boleto | F28: 30510 | G28: 158.3
E29: RV TECNOLOGIA S A | G29: 0
B30: 45721 | C30: 0 | D30: 0 | E30: 798 BB Rende Fácil | F30: 9903 | G30: 476.45
E31: Rende Facil | G31: 0
B32: 45722 | C32: 128 | D32: 99021 | E32: 870 Transferência recebida | F32: 610128000064860 | G32: 2264.76
E33: 06/03 11:01 CLINICA CLINCORDIS | G33: 0
B34: 45722 | C34: 0 | D34: 14397 | E34: 821 Pix - Recebido | F34: 60925331558762 | G34: 105.6
E35: 06/03 09:25 17135621000185 PET SHOP RE | G35: 0
B36: 45722 | C36: 0 | D36: 14397 | E36: 821 Pix - Recebido | F36: 61003344259782 | G36: 1270
E37: 06/03 10:03 03319496000159 MEDCAL FARM | G37: 0
B38: 45722 | C38: 0 | D38: 14397 | E38: 821 Pix - Recebido | F38: 61544237632392 | G38: 170
E39: 06/03 15:44 00070250037432 BRUNO GABRI | G39: 0
B40: 45722 | C40: 1533 | D40: 99008 | E40: 234 Compra com Cartão | F40: 588893 | G40: 238.72
...

Sheet Abr
A1: Status | B1: Dt. balancete | C1: Ag. origem | D1: Lote | E1: Histórico | F1: Documento | G1: Valor R$ | H1: Fatura | I1: Tipo | J1: Hematologia = | K1: =SUMIF(I60:I843,"Hematologia", G60:G843) -> 88043.08 | L1: TOTAL = | M1: =SUBTOTAL(9,Abr!$G$2:$G$889) -> 786969.58
B2: 45747 | C2: 0 | D2: 0 | E2: 000 Saldo Anterior | G2: 0
B3: 45748 | C3: 0 | D3: 14175 | E3: 976 TED-Crédito em Conta | F3: 376064205 | G3: 1170
E4: 748 2207 03319496000159 MEDCAL FARMA H | G4: 0
B5: 45748 | C5: 0 | D5: 14397 | E5: 821 Pix - Recebido | F5: 11508273488002 | G5: 6500
E6: 01/04 15:08 32958432000104 SLE SERVICO | G6: 0
B7: 45748 | C7: 0 | D7: 14397 | E7: 821 Pix - Recebido | F7: 435338422459261 | G7: 299.82
E8: 01/04 15:57 01751313417 Nathaly Dandar | G8: 0
B9: 45748 | C9: 0 | D9: 14397 | E9: 821 Pix - Recebido | F9: 435557650544891 | G9: 3200
E10: 01/04 22:02 01692863479 ANDERSON V OLI | G10: 0
B11: 45748 | C11: 0 | D11: 13105 | E11: 109 Pagamento de Boleto | F11: 40101 | G11: 233.6
E12: RV TECNOLOGIA S A | G12: 0
B13: 45748 | C13: 0 | D13: 13105 | E13: 109 Pagamento de Boleto | F13: 40102 | G13: 94.6
E14: RV TECNOLOGIA S A | G14: 0
B15: 45748 | C15: 0 | D15: 13105 | E15: 109 Pagamento de Boleto | F15: 40103 | G15: 816.83
E16: MEDIARTE COMERCIO E SERVICOS D | G16: 0
B17: 45748 | C17: 0 | D17: 13105 | E17: 375 Impostos | F17: 40104 | G17: 1749.69
E18: RN TRIBUTACAO ICMS | G18: 0
B19: 45748 | C19: 0 | D19: 13105 | E19: 375 Impostos | F19: 40105 | G19: 927.23
E20: RN TRIBUTACAO ICMS | G20: 0
B21: 45748 | C21: 0 | D21: 13105 | E21: 109 Pagamento de Boleto | F21: 40106 | G21: 3802.32
E22: BANCO ITAUCARD S.A. | G22: 0
B23: 45748 | C23: 0 | D23: 13105 | E23: 109 Pagamento de Boleto | F23: 40107 | G23: 49.9
E24: PJBANK PAGAMENTOS S A_1 | G24: 0
B25: 45748 | C25: 0 | D25: 0 | E25: 351 BB Rende Fácil | F25: 9903 | G25: 3495.65
E26: Rende Facil | G26: 0
B27: 45749 | C27: 2084 | D27: 99021 | E27: 870 Transferência recebida | F27: 612084000112119 | G27: 1250
B28: 45749 | C28: 0 | D28: 14175 | E28: 976 TED-Crédito em Conta | F28: 376225160 | G28: 1000
E29: 748 2207 03319496000159 MEDCAL FARMA H | G29: 0
B30: 45749 | C30: 0 | D30: 14397 | E30: 821 Pix - Recebido | F30: 21004434335392 | G30: 1124.35
E31: 02/04 10:04 11006454000196 LAB DE ANAL | G31: 0
B32: 45749 | C32: 0 | D32: 14397 | E32: 821 Pix - Recebido | F32: 21540276072622 | G32: 587.39
E33: 02/04 15:40 28155001000396 CLINICA SAN | G33: 0
B34: 45749 | C34: 0 | D34: 14397 | E34: 821 Pix - Recebido | F34: 435913651776191 | G34: 300
E35: 02/04 07:56 01692863479 ANDERSON V OLI | G35: 0
B36: 45749 | C36: 0 | D36: 14397 | E36: 821 Pix - Recebido | F36: 436279502192591 | G36: 3000
E37: 02/04 18:05 13640653000187 SILVA & OLI | G37: 0
B38: 45749 | C38: 1533 | D38: 99008 | E38: 234 Compra com Cartão | F38: 220617 | G38: 216.61
E39: 02/04 08:31 POSTO DINIZ - EMAUS | G39: 0
B40: 45749 | C40: 1533 | D40: 99008 | E40: 234 Compra com Cartão | F40: 965773 | G40: 120
...

Sheet Mai
A1: Status | B1: Dt. balancete | C1: Ag. origem | D1: Lote | E1: Histórico | F1: Documento | G1: Valor R$ | H1: Fatura | I1: Tipo | J1: Hematologia = | K1: =SUMIF(I8:I1067,"Hematologia", G8:G1098) -> 162800.05 | L1: Total = | M1: =SUBTOTAL(9,Mai!$G$2:$G$1098) -> 828438.8
B2: 45779 | C2: 0 | D2: 14175 | E2: 976 TED-Crédito em Conta | F2: 379709184 | G2: 5500 | H2: Medcal P/ Medcal via sicred
E3: 748 2207 03319496000159 MEDCAL FARMA H | G3: 0 | K3: =SUMIF(I10:I1069,"Hematologia", G10:G1069) -> 160895.3
B4: 45779 | C4: 0 | D4: 14397 | E4: 821 Pix - Recebido | F4: 21315345571562 | G4: 526.08
E5: 02/05 13:15 09522383000132 CENTRO A C | G5: 0 | K5: =SUMIF(I12:I1071,"Hematologia", G12:G1071) -> 160591.61
B6: 45779 | C6: 0 | D6: 14397 | E6: 821 Pix - Recebido | F6: 21445329484242 | G6: 45
E7: 02/05 14:45 00001692863479 ANDERSON V | G7: 0 | K7: =SUMIF(I14:I1073,"Hematologia", G14:G1073) -> 158923.53
A8: Baixado | B8: 45779 | C8: 0 | D8: 14138 | E8: 632 Ordem Bancária | F8: 202504300023214 | G8: 1904.75 | H8: 3168 e 3211 | I8: Hematologia | J8: Coagulação = | K8: =SUMIF(I8:I1067,"Coagulação", G8:G1067) -> 22726.57 | L8: Baixado = | M8: =SUMIF(A:A,"Baixado",G:G) -> 227636.03
E9: ESTADO DO RIO GRANDE D | G9: 0 | K9: =SUMIF(I16:I1075,"Hematologia", G16:G1075) -> 158923.53
A10: Baixado | B10: 45779 | C10: 0 | D10: 14138 | E10: 632 Ordem Bancária | F10: 202504300023219 | G10: 303.69 | H10: 3535 | I10: Hematologia | J10: TT/TTPA = | K10: =SUMIF(I8:I1060,"TT/TTPA", G8:G1067) -> 0 | L10: Pendente = | M10: =SUMIF(A:A,"Pendente",G:G) -> 0
E11: ESTADO DO RIO GRANDE D | G11: 0 | K11: =SUMIF(I18:I1077,"Hematologia", G18:G1077) -> 158923.53
A12: Baixado | B12: 45779 | C12: 0 | D12: 14138 | E12: 632 Ordem Bancária | F12: 202504300023227 | G12: 1668.08 | H12: 3487 | I12: Hematologia | J12: Ionograma = | K12: =SUMIF(I8:I1067,"Ionograma", G8:G1067) -> 3910.44
E13: ESTADO DO RIO GRANDE D | G13: 0
B14: 45779 | C14: 0 | D14: 14397 | E14: 821 Pix - Recebido | F14: 461924463784051 | G14: 299.34
E15: 02/05 10:27 12644969000184 I M M VAREL | G15: 0
B16: 45779 | C16: 0 | D16: 14397 | E16: 821 Pix - Recebido | F16: 461959284912981 | G16: 95
E17: 02/05 11:25 14054616000150 MAFALDO & S | G17: 0
B18: 45779 | C18: 0 | D18: 14397 | E18: 821 Pix - Recebido | F18: 462016847829531 | G18: 526.08
E19: 02/05 13:01 01850297444 JOSE DO EGITO | G19: 0
B20: 45779 | C20: 0 | D20: 14397 | E20: 821 Pix - Recebido | F20: 462151663820241 | G20: 3000
E21: 02/05 16:46 02400158436 João Hélio Oli | G21: 0
B22: 45779 | C22: 1533 | D22: 99008 | E22: 234 Compra com Cartão | F22: 14870 | G22: 102.09
E23: 02/05 16:07 FLOR E OLIVEIRA LTDA | G23: 0
B24: 45779 | C24: 1533 | D24: 99008 | E24: 234 Compra com Cartão | F24: 332442 | G24: 203.73
E25: 02/05 11:26 BRASIL EMBALAGEM | G25: 0
B26: 45779 | C26: 0 | D26: 13105 | E26: 109 Pagamento de Boleto | F26: 50201 | G26: 380.44
E27: BIONEXO S A | G27: 0
B28: 45779 | C28: 0 | D28: 13105 | E28: 109 Pagamento de Boleto | F28: 50202 | G28: 337.25
E29: AIRSUPPLY LOGISTICA T LTDA | G29: 0
B30: 45779 | C30: 0 | D30: 13105 | E30: 109 Pagamento de Boleto | F30: 50203 | G30: 1236.86
E31: BIOSUL PRODUTOS DIAGNOSTICOS L | G31: 0
B32: 45779 | C32: 0 | D32: 13105 | E32: 109 Pagamento de Boleto | F32: 50204 | G32: 1056
E33: Sanafarma Industria E Comercio | G33: 0
B34: 45779 | C34: 0 | D34: 13105 | E34: 109 Pagamento de Boleto | F34: 50205 | G34: 999.75
E35: BIOSYN INDUSTRIA E COMERCIO DE | G35: 0
B36: 45779 | C36: 0 | D36: 13105 | E36: 109 Pagamento de Boleto | F36: 50206 | G36: 2677.13
E37: EBRAM PROD LABORATORIAIS LTDA | G37: 0
B38: 45779 | C38: 0 | D38: 13105 | E38: 109 Pagamento de Boleto | F38: 50207 | G38: 179.42
E39: CRIL EMPREENDIMENTO AMBIENTAL | G39: 0
B40: 45779 | C40: 0 | D40: 13105 | E40: 109 Pagamento de Boleto | F40: 50208 | G40: 389.3
...

Sheet Jun
A1: Status | B1: Dt. balancete | C1: Ag. origem | D1: Lote | E1: Histórico | F1: Documento | G1: Valor R$ | H1: Fatura | I1: Tipo | J1: Hematologia = | K1: =SUMIF(I7:I1066,"Hematologia", G7:G1097) -> 63636.03 | L1: Total = | M1: =SUBTOTAL(9,Jun!$G$2:$G$922) -> 954127.35
B2: 45807 | C2: 0 | D2: 0 | E2: 000 Saldo Anterior | G2: 0
B3: 45810 | C3: 0 | D3: 14175 | E3: 976 TED-Crédito em Conta | F3: 383054221 | G3: 5000
E4: 748 2207 03319496000159 MEDCAL FARMA H
B5: 45810 | C5: 0 | D5: 14397 | E5: 821 Pix - Recebido | F5: 21533353591952 | G5: 153.5
E6: 02/06 15:33 51058729000150 WELL LAB LA
A7: Baixado | B7: 45810 | C7: 0 | D7: 14138 | E7: 632 Ordem Bancária | F7: 202505300004586 | G7: 1415.81 | H7: 3711 | I7: Hematologia | J7: Coagulação = | K7: =SUMIF(I7:I1066,"Coagulação", G7:G1097) -> 3753.14 | L7: Baixados = | M7: =SUMIF(A:A,"Baixado",G:G) -> 117011.21
E8: ESTADO DO RIO GRANDE D
A9: Baixado | B9: 45810 | C9: 0 | D9: 14138 | E9: 632 Ordem Bancária | F9: 202505300004594 | G9: 1668.08 | H9: 3490 | I9: Hematologia | J9: TT/TTPA = | K9: =SUMIF(I7:I1066,"TT/TTPA", G7:G1097) -> 0 | L9: Pendente = | M9: =SUMIF(A:A,"Pendente",G:G) -> 18455.07
E10: ESTADO DO RIO GRANDE D
A11: Baixado | B11: 45810 | C11: 0 | D11: 14138 | E11: 632 Ordem Bancária | F11: 202505300004598 | G11: 3112.28 | H11: 3512 | I11: Hematologia | J11: Ionograma = | K11: =SUMIF(I7:I1066,"Ionograma", G7:G1097) -> 48389.2
E12: ESTADO DO RIO GRANDE D
A13: Baixado | B13: 45810 | C13: 0 | D13: 14138 | E13: 632 Ordem Bancária | F13: 202505300004607 | G13: 274.56 | H13: 3713 | I13: Coagulação
E14: ESTADO DO RIO GRANDE D
B15: 45810 | C15: 1533 | D15: 99008 | E15: 234 Compra com Cartão | F15: 421945 | G15: 189.28
E16: 02/06 16:11 TM COMBUSTIVEIS
B17: 45810 | C17: 0 | D17: 13105 | E17: 375 Impostos | F17: 60201 | G17: 259.55
E18: RN TRIBUTACAO ICMS
B19: 45810 | C19: 0 | D19: 13105 | E19: 109 Pagamento de Boleto | F19: 60202 | G19: 2587.92
E20: BANCO VOTORANTIM S/A
B21: 45810 | C21: 0 | D21: 13105 | E21: 109 Pagamento de Boleto | F21: 60203 | G21: 2677.12
E22: EBRAM PROD LABORATORIAIS LTDA
B23: 45810 | C23: 0 | D23: 13105 | E23: 109 Pagamento de Boleto | F23: 60204 | G23: 116.9
E24: CDH DIAGNOSTICA
B25: 45810 | C25: 0 | D25: 13105 | E25: 109 Pagamento de Boleto | F25: 60205 | G25: 1320
E26: Sanafarma Industria E Comercio
B27: 45810 | C27: 0 | D27: 13105 | E27: 109 Pagamento de Boleto | F27: 60206 | G27: 422.92
E28: POLIFARMA DISTRIBUIDORA DE MED
B29: 45810 | C29: 0 | D29: 13105 | E29: 109 Pagamento de Boleto | F29: 60207 | G29: 387.38
E30: POLIFARMA DISTRIBUIDORA DE MED
B31: 45810 | C31: 0 | D31: 13105 | E31: 109 Pagamento de Boleto | F31: 60208 | G31: 554.02
E32: DISTR DE MEDI SANTA CRUZ LTDA
B33: 45810 | C33: 0 | D33: 13105 | E33: 109 Pagamento de Boleto | F33: 60209 | G33: 344.74
E34: DISTR DE MEDI SANTA CRUZ LTDA
B35: 45810 | C35: 0 | D35: 13105 | E35: 109 Pagamento de Boleto | F35: 60210 | G35: 447.56
E36: RIOGRANDENSE DISTRIBUIDORA LTD
B37: 45810 | C37: 0 | D37: 13105 | E37: 109 Pagamento de Boleto | F37: 60211 | G37: 37.4
E38: RIOGRANDENSE D LTDA
B39: 45810 | C39: 0 | D39: 13105 | E39: 109 Pagamento de Boleto | F39: 60212 | G39: 240.44
E40: FARMAUM NATAL M LTDA
...

Sheet Jul
A1: Status | B1: Dt. balancete | C1: Ag. origem | D1: Lote | E1: Histórico | F1: Documento | G1: Valor R$ | H1: Fatura | I1: Tipo | J1: Hematologia/165 = | K1: =SUMIF(I7:I1064,"Hematologia", G7:G1095) -> 123313.73 | L1: Total = | M1: =SUBTOTAL(9,Jul!$G$2:$G$1080) -> 1237754.4
B2: 45839 | C2: 0 | D2: 14175 | E2: 976 TED-Pag Fornecedores | F2: 35224465 | G2: 26626.61
E3: 104 1101 11802520000134 FUNDO MUNICIPA | G3: 0
B4: 45839 | C4: 0 | D4: 14175 | E4: 976 TED-Pag Fornecedores | F4: 35224508 | G4: 23761.4
E5: 104 1101 11802520000134 FUNDO MUNICIPA | G5: 0
A6: Baixado | B6: 45839 | C6: 0 | D6: 14138 | E6: 632 Ordem Bancária | F6: 202506300112173 | G6: 875.17 | H6: FT 3538 | I6: Coagulação | J6: Coagulação/141 = | K6: =SUMIF(I6:I1063,"Coagulação", G6:G1094) -> 5655.44 | L6: Baixados = | M6: =SUMIF(A:A,"Baixado",G:G) -> 239520.58
E7: ESTADO DO RIO GRANDE D | G7: 0
A8: Baixado | B8: 45839 | C8: 0 | D8: 14138 | E8: 632 Ordem Bancária | F8: 202506300132322 | G8: 3030.31 | H8: FTs 3094 e 3115 | I8: Ionograma | J8: TT/TTPA = | K8: =SUMIF(I6:I1063,"TT/TTPA", G6:G1094) -> 0 | L8: Pendente = | M8: =SUMIF(A:A,"Pendente",G:G) -> 10612.82
E9: ESTADO DO RIO GRANDE D | G9: 0
A10: Baixado | B10: 45839 | C10: 0 | D10: 14138 | E10: 632 Ordem Bancária | F10: 202506300132335 | G10: 1476.65 | H10: FT 3629 | I10: Ionograma | J10: Ionograma/220 = | K10: =SUMIF(I6:I1063,"Ionograma", G6:G1094) -> 109946.14
E11: ESTADO DO RIO GRANDE D | G11: 0
A12: Baixado | B12: 45839 | C12: 0 | D12: 14138 | E12: 632 Ordem Bancária | F12: 202506300132337 | G12: 1612.42 | H12: FT 2923 | I12: Ionograma
E13: ESTADO DO RIO GRANDE D | G13: 0
A14: Baixado | B14: 45839 | C14: 0 | D14: 14138 | E14: 632 Ordem Bancária | F14: 202506300132339 | G14: 1553.66 | H14: FT 3675 | I14: Ionograma
E15: ESTADO DO RIO GRANDE D | G15: 0
A16: Baixado | B16: 45839 | C16: 0 | D16: 14138 | E16: 632 Ordem Bancária | F16: 202506300132346 | G16: 1476.65 | H16: FT 3671 | I16: Ionograma
E17: ESTADO DO RIO GRANDE D | G17: 0
A18: Baixado | B18: 45839 | C18: 0 | D18: 14138 | E18: 632 Ordem Bancária | F18: 202506300132347 | G18: 589.59 | H18: FTs 3715 | I18: Coagulação
E19: ESTADO DO RIO GRANDE D | G19: 0
A20: Baixado | B20: 45839 | C20: 0 | D20: 14138 | E20: 632 Ordem Bancária | F20: 202506300132351 | G20: 17518.9 | H20: FTs 2445.1, 2447.1, 2915.1, 2921.1, 2926 | I20: Ionograma | J20: R$ 15691,68 - No extrato não coube todas as faturas.
E21: ESTADO DO RIO GRANDE D | G21: 0
A22: Baixado | B22: 45839 | C22: 0 | D22: 14138 | E22: 632 Ordem Bancária | F22: 202506300132352 | G22: 6164.33 | H22: FTs 3707 | I22: Hematologia
E23: ESTADO DO RIO GRANDE D | G23: 0
A24: Baixado | B24: 45839 | C24: 0 | D24: 14138 | E24: 632 Ordem Bancária | F24: 202506300132354 | G24: 1553.66 | H24: FT 3696 | I24: Ionograma
E25: ESTADO DO RIO GRANDE D | G25: 0
A26: Baixado | B26: 45839 | C26: 0 | D26: 14138 | E26: 632 Ordem Bancária | F26: 202506300132359 | G26: 1476.65 | H26: FT 3685 | I26: Ionograma
E27: ESTADO DO RIO GRANDE D | G27: 0
A28: Baixado | B28: 45839 | C28: 0 | D28: 14138 | E28: 632 Ordem Bancária | F28: 202506300132363 | G28: 1476.65 | H28: FT 2753 | I28: Ionograma
E29: ESTADO DO RIO GRANDE D | G29: 0
A30: Baixado | B30: 45839 | C30: 0 | D30: 14138 | E30: 632 Ordem Bancária | F30: 202506300132365 | G30: 1553.66 | H30: FT 3605 | I30: Ionograma
E31: ESTADO DO RIO GRANDE D | G31: 0
A32: Baixado | B32: 45839 | C32: 0 | D32: 14138 | E32: 632 Ordem Bancária | F32: 202506300132367 | G32: 1476.65 | H32: FT 3594 | I32: Ionograma
E33: ESTADO DO RIO GRANDE D | G33: 0
A34: Baixado | B34: 45839 | C34: 0 | D34: 14138 | E34: 632 Ordem Bancária | F34: 202506300132369 | G34: 1476.65 | H34: FT 2335 | I34: Ionograma
E35: ESTADO DO RIO GRANDE D | G35: 0
A36: Baixado | B36: 45839 | C36: 0 | D36: 14138 | E36: 632 Ordem Bancária | F36: 202506300132371 | G36: 3237.94 | H36: FATURA 3524 | I36: Hematologia
E37: ESTADO DO RIO GRANDE D | G37: 0
A38: Baixado | B38: 45839 | C38: 0 | D38: 14138 | E38: 632 Ordem Bancária | F38: 202506300132372 | G38: 1668.08 | H38: FATURA 3481 | I38: Hematologia
E39: ESTADO DO RIO GRANDE D | G39: 0
B40: 45839 | C40: 1533 | D40: 99015 | E40: 470 Transferência enviada | F40: 551845000113366 | G40: 3605.31
...

Sheet Ago
A1: Status | B1: Dt. balancete | C1: Ag. origem | D1: Lote | E1: Histórico | F1: Documento | G1: Valor R$ | H1: Fatura | I1: Tipo | J1: Hematologia/165 = | K1: =SUMIF(I:I,"Hematologia", G:G) -> 72031.1 | L1: Total = | M1: =SUBTOTAL(9,Ago!$G$2:$G$1026) -> 1072735.4
B2: 45869 | C2: 0 | D2: 0 | E2: 000 Saldo Anterior | G2: 0
B3: 45870 | C3: 0 | D3: 14397 | E3: 821 Pix - Recebido | F3: 11032315887311 | G3: 4409
E4: 01/08 10:32 51936203000125 Cliniclab E | G4: 0
B5: 45870 | C5: 0 | D5: 14397 | E5: 821 Pix - Recebido | F5: 11347282025861 | G5: 5000
E6: 01/08 13:47 83738657487 MAGNUS SOARES | G6: 0
A7: Baixado | B7: 45870 | C7: 0 | D7: 14138 | E7: 632 Ordem Bancária | F7: 202507310001855 | G7: 1241.98 | H7: Fatura 3889 | I7: Hematologia | J7: Coagulação/141 = | K7: =SUMIF(I:I,"Coagulação", G:G) -> 9345.69 | L7: Baixados = | M7: =SUMIF(A:A,"Baixado",G:G) -> 171794.18
E8: ESTADO DO RIO GRANDE D | G8: 0
A9: Baixado | B9: 45870 | C9: 0 | D9: 14138 | E9: 632 Ordem Bancária | F9: 202507310001857 | G9: 1232.84 | H9: Fatura 3849 | I9: Hematologia | J9: Ionograma/220 = | K9: =SUMIF(I:I,"Ionograma", G:G) -> 40910.9 | L9: Pendente = | M9: =SUMIF(A:A,"Pendente",G:G) -> 5474.25
E10: ESTADO DO RIO GRANDE D | G10: 0
A11: Baixado | B11: 45870 | C11: 0 | D11: 14138 | E11: 632 Ordem Bancária | F11: 202507310001859 | G11: 4167.09 | H11: Fatura 3897 e 3848 | I11: Hematologia
E12: ESTADO DO RIO GRANDE D | G12: 0
A13: Baixado | B13: 45870 | C13: 0 | D13: 14138 | E13: 632 Ordem Bancária | F13: 202507310001861 | G13: 2439.98 | H13: Fatura 3914 | I13: Hematologia
E14: ESTADO DO RIO GRANDE D | G14: 0
A15: Baixado | B15: 45870 | C15: 0 | D15: 14138 | E15: 632 Ordem Bancária | F15: 202507310001865 | G15: 1668.08 | H15: FATURA 3836 | I15: Hematologia
E16: ESTADO DO RIO GRANDE D | G16: 0
A17: Baixado | B17: 45870 | C17: 0 | D17: 14138 | E17: 632 Ordem Bancária | F17: 202507310001868 | G17: 1063.96 | H17: FATURA 3903 | I17: Hematologia
E18: ESTADO DO RIO GRANDE D | G18: 0
A19: Baixado | B19: 45870 | C19: 0 | D19: 14138 | E19: 632 Ordem Bancária | F19: 202507310001871 | G19: 1668.08 | H19: FATURA 3840 | I19: Hematologia
E20: ESTADO DO RIO GRANDE D | G20: 0
B21: 45870 | C21: 1533 | D21: 99015 | E21: 470 Transferência enviada | F21: 551845000113366 | G21: 3605.31
E22: 01/08 15:37 JONATAN EDUARDO M SILVA | G22: 0
B23: 45870 | C23: 1533 | D23: 99015 | E23: 470 Transferência enviada | F23: 552035000108588 | G23: 3687.48
E24: 01/08 15:28 RHOZA MARIA ARAUJO DE ME | G24: 0
B25: 45870 | C25: 0 | D25: 13105 | E25: 144 Pix - Enviado | F25: 80101 | G25: 154.88
E26: 01/08 08:42 Posto Qualy Boa Esperanca | G26: 0
B27: 45870 | C27: 0 | D27: 13105 | E27: 109 Pagamento de Boleto | F27: 80102 | G27: 378.65
E28: DISTR DE MEDI SANTA CRUZ LTDA | G28: 0
B29: 45870 | C29: 0 | D29: 13105 | E29: 109 Pagamento de Boleto | F29: 80103 | G29: 302.35
E30: RV TECNOLOGIA S A | G30: 0
B31: 45870 | C31: 0 | D31: 13105 | E31: 109 Pagamento de Boleto | F31: 80104 | G31: 677.93
E32: POLIFARMA DISTRIBUIDORA DE MED | G32: 0
B33: 45870 | C33: 0 | D33: 13105 | E33: 109 Pagamento de Boleto | F33: 80105 | G33: 555.51
E34: POLIFARMA DISTRIBUIDORA DE MED | G34: 0
B35: 45870 | C35: 0 | D35: 13105 | E35: 109 Pagamento de Boleto | F35: 80106 | G35: 459.42
E36: POLIFARMA DISTRIBUIDORA DE MED | G36: 0
B37: 45870 | C37: 0 | D37: 13105 | E37: 109 Pagamento de Boleto | F37: 80107 | G37: 190.37
E38: PROFARMA DISTRIBUIDORA DE PROD | G38: 0
B39: 45870 | C39: 0 | D39: 13105 | E39: 144 Pix - Enviado | F39: 80108 | G39: 16000
E40: 01/08 14:34 M & S LOCACOES LTDA | G40: 0
...

Sheet Set
J1: Hematologia/165 = | K1: =SUMIF(I:I,"Hematologia",G:G) -> 28935.3 | L1: Total = | M1: =SUM(G51:G723) -> 580645.5
J2: Coagulação/141 = | K2: =SUMIF(I:I,"Coagulação",G:G) -> 9797.35 | L2: Baixados = | M2: =SUMIF(A:A,"Baixado",G:G) -> 69516.62
J3: Ionograma/220 = | K3: =SUMIF(I:I,"Ionograma",G:G) -> 31469.53 | L3: Pendente = | M3: =SUMIF(A:A,"Pendente",G:G) -> 22728.27
A4: Status | B4: Dt. balancete | C4: Ag. origem | D4: Lote | E4: Histórico | F4: Documento | G4: Valor R$ | H4: Fatura | I4: Tipo
B5: 45901 | C5: 0 | D5: 14175 | E5: 976 TED-Pag Fornecedores | F5: 35353866 | G5: 6542.84
E6: 104 7853 10709689000181 FUNDO DE SAUDE
B7: 45901 | C7: 0 | D7: 14175 | E7: 976 TED-Crédito em Conta | F7: 35374770 | G7: 4500
E8: 748 2207 03319496000159 MEDCAL FARMA H
B9: 45901 | C9: 0 | D9: 14397 | E9: 821 Pix - Recebido | F9: 11605065598831 | G9: 1651.9
E10: 01/09 16:05 48138959487 HUDMAR DE SOUS
B11: 45901 | C11: 1533 | D11: 99008 | E11: 234 Compra com Cartão | F11: 231865 | G11: 119.66
E12: 01/09 21:04 POSTO QUALY
B13: 45901 | C13: 0 | D13: 13105 | E13: 109 Pagamento de Boleto | F13: 90101 | G13: 2361.61
E14: EBRAM PROD LABORATORIAIS LTDA
B15: 45901 | C15: 0 | D15: 13105 | E15: 375 Impostos | F15: 90102 | G15: 620.26
E16: RN TRIBUTACAO ICMS
B17: 45901 | C17: 0 | D17: 13105 | E17: 375 Impostos | F17: 90103 | G17: 644.51
E18: RN TRIBUTACAO ICMS
B19: 45901 | C19: 0 | D19: 13105 | E19: 109 Pagamento de Boleto | F19: 90104 | G19: 244.05
E20: RV TECNOLOGIA S A
B21: 45901 | C21: 0 | D21: 13105 | E21: 109 Pagamento de Boleto | F21: 90105 | G21: 1192.58
E22: DISTR DE MEDI SANTA CRUZ LTDA
B23: 45901 | C23: 0 | D23: 13105 | E23: 109 Pagamento de Boleto | F23: 90106 | G23: 286.17
E24: POLIFARMA DISTRIBUIDORA DE MED
B25: 45901 | C25: 0 | D25: 13105 | E25: 109 Pagamento de Boleto | F25: 90107 | G25: 265.34
E26: FARMAUM NATAL M LTDA
B27: 45901 | C27: 0 | D27: 13105 | E27: 109 Pagamento de Boleto | F27: 90108 | G27: 191.44
E28: FARMAUM NATAL M LTDA
B29: 45901 | C29: 0 | D29: 13105 | E29: 109 Pagamento de Boleto | F29: 90109 | G29: 446.22
E30: ANDRADE DISTRIBUIDORA LTDA
B31: 45901 | C31: 0 | D31: 13105 | E31: 375 Impostos | F31: 90110 | G31: 353.36
E32: RN TRIBUTACAO ICMS
B33: 45901 | C33: 0 | D33: 13105 | E33: 375 Impostos | F33: 90111 | G33: 246.71
E34: RN TRIBUTACAO ICMS
B35: 45901 | C35: 0 | D35: 13105 | E35: 109 Pagamento de Boleto | F35: 90112 | G35: 176.43
E36: DISTR DE MEDI SANTA CRUZ LTDA
B37: 45901 | C37: 0 | D37: 13105 | E37: 109 Pagamento de Boleto | F37: 90113 | G37: 446.78
E38: POLIFARMA DISTRIBUIDORA DE MED
B39: 45901 | C39: 0 | D39: 13105 | E39: 109 Pagamento de Boleto | F39: 90114 | G39: 233.5
E40: DISTRIBUIDORA SERIDO
...

Sheet Out
J1: Hematologia/165 = | K1: =SUMIF(I:I,"Hematologia", G:G) -> 49957.2 | L1: Total = | M1: =SUBTOTAL(9,Tabelaout[Valor R$]) -> 107252.61
J2: Coagulação/141 = | K2: =SUMIF(I:I,"Coagulação", G:G) -> 12900.83 | L2: Baixados = | M2: =SUMIF(A:A,"Baixado",G:G) -> 105318.02
J3: Ionograma/220 = | K3: =SUMIF(I:I,"Ionograma", G:G) -> 42459.99 | L3: Pendente = | M3: =SUMIF(A:A,"Pendente",G:G) -> 1934.59
A5: Status | B5: Dt. balancete | C5: Ag. origem | D5: Lote | E5: Histórico | F5: Documento | G5: Valor R$ | H5: Fatura | I5: Tipo
B6: 45930 | C6: 0 | D6: 0 | E6: 000 Saldo Anterior | G6: 0
B7: 45931 | C7: 2256 | D7: 99021 | E7: 870 Transferência recebida | F7: 612256000106555 | G7: 554.15
E8: 01/10 15:27 LAB A C DANTAS LTDA
B9: 45931 | C9: 0 | D9: 14175 | E9: 976 TED-Crédito em Conta | F9: 396438844 | G9: 8000
E10: 748 2207 03319496000159 MEDCAL FARMA H
B11: 45931 | C11: 0 | D11: 14397 | E11: 821 Pix - Recebido | F11: 11105506014392 | G11: 800
E12: 01/10 11:05 48899285000170 GROUP PMD
B13: 45931 | C13: 0 | D13: 14397 | E13: 821 Pix - Recebido | F13: 11515508888002 | G13: 4036.15
E14: 01/10 15:15 20897601000156 BIO ANALISE
B15: 45931 | C15: 0 | D15: 14397 | E15: 821 Pix - Recebido | F15: 11604080538762 | G15: 148.5
E16: 01/10 16:04 35256106000135 PROANALISES
B17: 45931 | C17: 0 | D17: 14397 | E17: 821 Pix - Recebido | F17: 11658498892932 | G17: 638.59
E18: 01/10 16:58 22673815000174 SOUZA E CAR
A19: Baixado | B19: 45931 | C19: 0 | D19: 14138 | E19: 632 Ordem Bancária | F19: 202509300020089 | G19: 289.27 | H19: 4007 | I19: Coagulação
E20: ESTADO DO RIO GRANDE D
A21: Baixado | B21: 45931 | C21: 0 | D21: 14138 | E21: 632 Ordem Bancária | F21: 202509300020103 | G21: 926.63 | H21: 4008 | I21: Coagulação
E22: ESTADO DO RIO GRANDE D
A23: Baixado | B23: 45931 | C23: 0 | D23: 14138 | E23: 632 Ordem Bancária | F23: 202509300020116 | G23: 609.28 | H23: 3997 | I23: Coagulação
E24: ESTADO DO RIO GRANDE D
A25: Baixado | B25: 45931 | C25: 0 | D25: 14138 | E25: 632 Ordem Bancária | F25: 202509300020118 | G25: 609.28 | H25: 3996 | I25: Coagulação
E26: ESTADO DO RIO GRANDE D
B27: 45931 | C27: 1533 | D27: 99008 | E27: 234 Compra com Cartão | F27: 540522 | G27: 188.83
E28: 01/10 08:15 POSTO DINIZ - EMAUS
B29: 45931 | C29: 0 | D29: 13105 | E29: 109 Pagamento de Boleto | F29: 100101 | G29: 1632.23
E30: LABOR IMPORT COMERCIAL IMPORTA
B31: 45931 | C31: 0 | D31: 13105 | E31: 109 Pagamento de Boleto | F31: 100102 | G31: 410.53
E32: INFOX
B33: 45931 | C33: 0 | D33: 13105 | E33: 109 Pagamento de Boleto | F33: 100103 | G33: 186.5
E34: INFOX
B35: 45931 | C35: 0 | D35: 13105 | E35: 109 Pagamento de Boleto | F35: 100104 | G35: 816.5
E36: MEDIARTE COMERCIO E SERVICOS D
B37: 45931 | C37: 0 | D37: 13105 | E37: 109 Pagamento de Boleto | F37: 100105 | G37: 96.96
E38: PJBANK PAGAMENTOS S A_1
B39: 45931 | C39: 0 | D39: 13105 | E39: 109 Pagamento de Boleto | F39: 100106 | G39: 224.48
E40: DISTR DE MEDI SANTA CRUZ LTDA
B41: 45931 | C41: 0 | D41: 13105 | E41: 109 Pagamento de Boleto | F41: 100107 | G41: 37.69
...

Sheet Nov
A1: Status | B1: Dt. balancete | C1: Ag. origem | D1: Lote | E1: Histórico | F1: Documento | G1: Valor R$ | H1: Fatura | I1: Tipo | K1: Hematologia/165 = | L1: =SUMIF(J:J,"Hematologia", H:H) -> 0 | M1: Total = | N1: =SUBTOTAL(9,Ago!$G$2:$G$1026) -> 1072735.4
K2: Coagulação/141 = | L2: =SUMIF(J:J,"Coagulação", H:H) -> 0 | M2: Baixados = | N2: =SUMIF(B:B,"Baixado",H:H) -> 0
K3: TT/TTPA = | L3: =SUMIF(J:J,"TT/TTPA", H:H) -> 0 | M3: Pendente = | N3: =SUMIF(B:B,"Pendente",H:H) -> 0
K4: Ionograma/220 = | L4: =SUMIF(J:J,"Ionograma", H:H) -> 0

Sheet Dez
A1: Status | B1: Dt. balancete | C1: Ag. origem | D1: Lote | E1: Histórico | F1: Documento | G1: Valor R$ | H1: Fatura | I1: Tipo | K1: Hematologia/165 = | L1: =SUMIF(J:J,"Hematologia", H:H) -> 0 | M1: Total = | N1: =SUBTOTAL(9,Ago!$G$2:$G$1026) -> 1072735.4
K2: Coagulação/141 = | L2: =SUMIF(J:J,"Coagulação", H:H) -> 0 | M2: Baixados = | N2: =SUMIF(B:B,"Baixado",H:H) -> 0
K3: TT/TTPA = | L3: =SUMIF(J:J,"TT/TTPA", H:H) -> 0 | M3: Pendente = | N3: =SUMIF(B:B,"Pendente",H:H) -> 0
K4: Ionograma/220 = | L4: =SUMIF(J:J,"Ionograma", H:H) -> 0
